import {
  throwError,
  throwCustomError,
  resolveValue,
  MyAwesomeError,
  rejectCustomError,
} from './index';

describe('resolveValue', () => {
  test('should resolve provided value', async () => {
    const value = 7;
    const result = await resolveValue(value);
    expect(result).toBe(value);
  });
});

describe('throwError', () => {
  test('should throw error with provided message', () => {
    const msg = 'This is a custom error message';
    expect(() => throwError(msg)).toThrow(msg);
  });

  test('should throw error with default message if message is not provided', () => {
    expect(() => throwError()).toThrow('Oops!');
  });
});

describe('throwCustomError', () => {
  test('should throw custom error', () => {
    expect(() => throwCustomError()).toThrow(MyAwesomeError);
    expect(() => throwCustomError()).toThrow(
      'This is my awesome custom error!',
    );
  });
});

describe('rejectCustomError', () => {
  test('should reject custom error', async () => {
    await expect(rejectCustomError()).rejects.toThrow(MyAwesomeError);
    await expect(rejectCustomError()).rejects.toThrow(
      'This is my awesome custom error!',
    );
  });
});
